Workbook

Sheet S3 Regular Season Stats
A1: 4 | B1: Kills | C1: Assists | D1: Deaths | E1: Total Damage | F1: ADR | G1: Kill Diff. | M1: Category | N1: Leader | O1: Value
A2: Adam | B2: =SUMIF('S3 Regular Season'!A:A, A2, 'S3 Regular Season'!B:B) + SUMIF('S3 Regular Season'!K:K, A2, 'S3 Regular Season'!L:L) -> 0 | C2: =SUMIF('S3 Regular Season'!A:A, A2, 'S3 Regular Season'!C:C) + SUMIF('S3 Regular Season'!K:K, A2, 'S3 Regular Season'!M:M) -> 0 | D2: =SUMIF('S3 Regular Season'!A:A, A2, 'S3 Regular Season'!D:D) + SUMIF('S3 Regular Season'!K:K, A2, 'S3 Regular Season'!N:N) -> 0 | E2: =SUMIF('S3 Regular Season'!A:A, A2, 'S3 Regular Season'!F:F) + SUMIF('S3 Regular Season'!K:K, A2, 'S3 Regular Season'!P:P) -> 0 | F2: =IFERROR(SUMIF(S3_Stats[4], A2, S3_Stats[Total Damage]) / SUMIF(S3_Game_Stats[Name], A2, S3_Game_Stats[Rounds Played]), 0) -> 0 | G2: =SUMIF(S3_Stats[4], A2, S3_Stats[Kills]) - SUMIF(S3_Stats[4], A2, S3_Stats[Deaths]) -> 0 | M2: Kills | N2: {=INDIRECT("A"&MATCH(MAX(S3_Stats[Kills]), S3_Stats[Kills], 0)+1)} -> Adam | O2: =MAX(S3_Stats[Kills]) -> 0
A3: Andrew | B3: =SUMIF('S3 Regular Season'!A:A, A3, 'S3 Regular Season'!B:B) + SUMIF('S3 Regular Season'!K:K, A3, 'S3 Regular Season'!L:L) -> 0 | C3: =SUMIF('S3 Regular Season'!A:A, A3, 'S3 Regular Season'!C:C) + SUMIF('S3 Regular Season'!K:K, A3, 'S3 Regular Season'!M:M) -> 0 | D3: =SUMIF('S3 Regular Season'!A:A, A3, 'S3 Regular Season'!D:D) + SUMIF('S3 Regular Season'!K:K, A3, 'S3 Regular Season'!N:N) -> 0 | E3: =SUMIF('S3 Regular Season'!A:A, A3, 'S3 Regular Season'!F:F) + SUMIF('S3 Regular Season'!K:K, A3, 'S3 Regular Season'!P:P) -> 0 | F3: =IFERROR(SUMIF(S3_Stats[4], A3, S3_Stats[Total Damage]) / SUMIF(S3_Game_Stats[Name], A3, S3_Game_Stats[Rounds Played]), 0) -> 0 | G3: =SUMIF(S3_Stats[4], A3, S3_Stats[Kills]) - SUMIF(S3_Stats[4], A3, S3_Stats[Deaths]) -> 0 | M3: Assists | N3: {=INDIRECT("A"&MATCH(MAX(S3_Stats[Assists]), S3_Stats[Assists], 0)+1)} -> Adam | O3: =MAX(S3_Stats[Assists]) -> 0
A4: Brian | B4: =SUMIF('S3 Regular Season'!A:A, A4, 'S3 Regular Season'!B:B) + SUMIF('S3 Regular Season'!K:K, A4, 'S3 Regular Season'!L:L) -> 0 | C4: =SUMIF('S3 Regular Season'!A:A, A4, 'S3 Regular Season'!C:C) + SUMIF('S3 Regular Season'!K:K, A4, 'S3 Regular Season'!M:M) -> 0 | D4: =SUMIF('S3 Regular Season'!A:A, A4, 'S3 Regular Season'!D:D) + SUMIF('S3 Regular Season'!K:K, A4, 'S3 Regular Season'!N:N) -> 0 | E4: =SUMIF('S3 Regular Season'!A:A, A4, 'S3 Regular Season'!F:F) + SUMIF('S3 Regular Season'!K:K, A4, 'S3 Regular Season'!P:P) -> 0 | F4: =IFERROR(SUMIF(S3_Stats[4], A4, S3_Stats[Total Damage]) / SUMIF(S3_Game_Stats[Name], A4, S3_Game_Stats[Rounds Played]), 0) -> 0 | G4: =SUMIF(S3_Stats[4], A4, S3_Stats[Kills]) - SUMIF(S3_Stats[4], A4, S3_Stats[Deaths]) -> 0 | M4: Least Deaths | N4: {=INDIRECT("A"&MATCH(MIN(S3_Stats[Deaths]), S3_Stats[Deaths], 0)+1)} -> Adam | O4: =MIN(S3_Stats[Deaths]) -> 0
A5: Dan | B5: =SUMIF('S3 Regular Season'!A:A, A5, 'S3 Regular Season'!B:B) + SUMIF('S3 Regular Season'!K:K, A5, 'S3 Regular Season'!L:L) -> 0 | C5: =SUMIF('S3 Regular Season'!A:A, A5, 'S3 Regular Season'!C:C) + SUMIF('S3 Regular Season'!K:K, A5, 'S3 Regular Season'!M:M) -> 0 | D5: =SUMIF('S3 Regular Season'!A:A, A5, 'S3 Regular Season'!D:D) + SUMIF('S3 Regular Season'!K:K, A5, 'S3 Regular Season'!N:N) -> 0 | E5: =SUMIF('S3 Regular Season'!A:A, A5, 'S3 Regular Season'!F:F) + SUMIF('S3 Regular Season'!K:K, A5, 'S3 Regular Season'!P:P) -> 0 | F5: =IFERROR(SUMIF(S3_Stats[4], A5, S3_Stats[Total Damage]) / SUMIF(S3_Game_Stats[Name], A5, S3_Game_Stats[Rounds Played]), 0) -> 0 | G5: =SUMIF(S3_Stats[4], A5, S3_Stats[Kills]) - SUMIF(S3_Stats[4], A5, S3_Stats[Deaths]) -> 0 | M5: K/D | N5: {=INDIRECT("A"&MATCH(MAX(S3_Kill_Stats[K/D]), S3_Kill_Stats[K/D], 0)+13)} -> #N/A | O5: =MAX(S3_Kill_Stats[K/D]) -> 0
A6: Emanuel | B6: =SUMIF('S3 Regular Season'!A:A, A6, 'S3 Regular Season'!B:B) + SUMIF('S3 Regular Season'!K:K, A6, 'S3 Regular Season'!L:L) -> 0 | C6: =SUMIF('S3 Regular Season'!A:A, A6, 'S3 Regular Season'!C:C) + SUMIF('S3 Regular Season'!K:K, A6, 'S3 Regular Season'!M:M) -> 0 | D6: =SUMIF('S3 Regular Season'!A:A, A6, 'S3 Regular Season'!D:D) + SUMIF('S3 Regular Season'!K:K, A6, 'S3 Regular Season'!N:N) -> 0 | E6: =SUMIF('S3 Regular Season'!A:A, A6, 'S3 Regular Season'!F:F) + SUMIF('S3 Regular Season'!K:K, A6, 'S3 Regular Season'!P:P) -> 0 | F6: =IFERROR(SUMIF(S3_Stats[4], A6, S3_Stats[Total Damage]) / SUMIF(S3_Game_Stats[Name], A6, S3_Game_Stats[Rounds Played]), 0) -> 0 | G6: =SUMIF(S3_Stats[4], A6, S3_Stats[Kills]) - SUMIF(S3_Stats[4], A6, S3_Stats[Deaths]) -> 0 | M6: Most Rounds Played | N6: {=INDIRECT("A"&MATCH(MAX(S3_Game_Stats[Rounds Played]), S3_Game_Stats[Rounds Played], 0)+25)} -> Michael | O6: =MAX(S3_Game_Stats[Rounds Played]) -> 0
A7: Eric | B7: =SUMIF('S3 Regular Season'!A:A, A7, 'S3 Regular Season'!B:B) + SUMIF('S3 Regular Season'!K:K, A7, 'S3 Regular Season'!L:L) -> 0 | C7: =SUMIF('S3 Regular Season'!A:A, A7, 'S3 Regular Season'!C:C) + SUMIF('S3 Regular Season'!K:K, A7, 'S3 Regular Season'!M:M) -> 0 | D7: =SUMIF('S3 Regular Season'!A:A, A7, 'S3 Regular Season'!D:D) + SUMIF('S3 Regular Season'!K:K, A7, 'S3 Regular Season'!N:N) -> 0 | E7: =SUMIF('S3 Regular Season'!A:A, A7, 'S3 Regular Season'!F:F) + SUMIF('S3 Regular Season'!K:K, A7, 'S3 Regular Season'!P:P) -> 0 | F7: =IFERROR(SUMIF(S3_Stats[4], A7, S3_Stats[Total Damage]) / SUMIF(S3_Game_Stats[Name], A7, S3_Game_Stats[Rounds Played]), 0) -> 0 | G7: =SUMIF(S3_Stats[4], A7, S3_Stats[Kills]) - SUMIF(S3_Stats[4], A7, S3_Stats[Deaths]) -> 0 | M7: Least Rounds Played | N7: {=INDIRECT("A"&MATCH(MIN(S3_Game_Stats[Rounds Played]), S3_Game_Stats[Rounds Played], 0)+25)} -> Michael | O7: =MIN(S3_Game_Stats[Rounds Played]) -> 0
A8: Fred | B8: =SUMIF('S3 Regular Season'!A:A, A8, 'S3 Regular Season'!B:B) + SUMIF('S3 Regular Season'!K:K, A8, 'S3 Regular Season'!L:L) -> 0 | C8: =SUMIF('S3 Regular Season'!A:A, A8, 'S3 Regular Season'!C:C) + SUMIF('S3 Regular Season'!K:K, A8, 'S3 Regular Season'!M:M) -> 0 | D8: =SUMIF('S3 Regular Season'!A:A, A8, 'S3 Regular Season'!D:D) + SUMIF('S3 Regular Season'!K:K, A8, 'S3 Regular Season'!N:N) -> 0 | E8: =SUMIF('S3 Regular Season'!A:A, A8, 'S3 Regular Season'!F:F) + SUMIF('S3 Regular Season'!K:K, A8, 'S3 Regular Season'!P:P) -> 0 | F8: =IFERROR(SUMIF(S3_Stats[4], A8, S3_Stats[Total Damage]) / SUMIF(S3_Game_Stats[Name], A8, S3_Game_Stats[Rounds Played]), 0) -> 0 | G8: =SUMIF(S3_Stats[4], A8, S3_Stats[Kills]) - SUMIF(S3_Stats[4], A8, S3_Stats[Deaths]) -> 0 | M8: Best Round WR% | N8: {=INDIRECT("A"&MATCH(MAX(S3_Game_Stats[Round WR %]), S3_Game_Stats[Round WR %], 0)+25)} -> #N/A | O8: =MAX(S3_Game_Stats[Round WR %]) -> 0
A9: Kevin | B9: =SUMIF('S3 Regular Season'!A:A, A9, 'S3 Regular Season'!B:B) + SUMIF('S3 Regular Season'!K:K, A9, 'S3 Regular Season'!L:L) -> 0 | C9: =SUMIF('S3 Regular Season'!A:A, A9, 'S3 Regular Season'!C:C) + SUMIF('S3 Regular Season'!K:K, A9, 'S3 Regular Season'!M:M) -> 0 | D9: =SUMIF('S3 Regular Season'!A:A, A9, 'S3 Regular Season'!D:D) + SUMIF('S3 Regular Season'!K:K, A9, 'S3 Regular Season'!N:N) -> 0 | E9: =SUMIF('S3 Regular Season'!A:A, A9, 'S3 Regular Season'!F:F) + SUMIF('S3 Regular Season'!K:K, A9, 'S3 Regular Season'!P:P) -> 0 | F9: =IFERROR(SUMIF(S3_Stats[4], A9, S3_Stats[Total Damage]) / SUMIF(S3_Game_Stats[Name], A9, S3_Game_Stats[Rounds Played]), 0) -> 0 | G9: =SUMIF(S3_Stats[4], A9, S3_Stats[Kills]) - SUMIF(S3_Stats[4], A9, S3_Stats[Deaths]) -> 0 | M9: Most Damage | N9: {=INDIRECT("A"&MATCH(MAX(S3_Stats[Total Damage]), S3_Stats[Total Damage], 0)+1)} -> Adam | O9: =MAX(S3_Stats[Total Damage]) -> 0
A10: Michael | B10: =SUMIF('S3 Regular Season'!A:A, A10, 'S3 Regular Season'!B:B) + SUMIF('S3 Regular Season'!K:K, A10, 'S3 Regular Season'!L:L) -> 0 | C10: =SUMIF('S3 Regular Season'!A:A, A10, 'S3 Regular Season'!C:C) + SUMIF('S3 Regular Season'!K:K, A10, 'S3 Regular Season'!M:M) -> 0 | D10: =SUMIF('S3 Regular Season'!A:A, A10, 'S3 Regular Season'!D:D) + SUMIF('S3 Regular Season'!K:K, A10, 'S3 Regular Season'!N:N) -> 0 | E10: =SUMIF('S3 Regular Season'!A:A, A10, 'S3 Regular Season'!F:F) + SUMIF('S3 Regular Season'!K:K, A10, 'S3 Regular Season'!P:P) -> 0 | F10: =IFERROR(SUMIF(S3_Stats[4], A10, S3_Stats[Total Damage]) / SUMIF(S3_Game_Stats[Name], A10, S3_Game_Stats[Rounds Played]), 0) -> 0 | G10: =SUMIF(S3_Stats[4], A10, S3_Stats[Kills]) - SUMIF(S3_Stats[4], A10, S3_Stats[Deaths]) -> 0 | M10: Most Dmg/Game | N10: {=INDIRECT("A"&MATCH(MAX(S3_Avg_Game_Stats[Dmg/Game]), S3_Avg_Game_Stats[Dmg/Game], 0)+38)} -> #N/A | O10: =MAX(S3_Avg_Game_Stats[Dmg/Game]) -> 0
A11: Sean | B11: =SUMIF('S3 Regular Season'!A:A, A11, 'S3 Regular Season'!B:B) + SUMIF('S3 Regular Season'!K:K, A11, 'S3 Regular Season'!L:L) -> 0 | C11: =SUMIF('S3 Regular Season'!A:A, A11, 'S3 Regular Season'!C:C) + SUMIF('S3 Regular Season'!K:K, A11, 'S3 Regular Season'!M:M) -> 0 | D11: =SUMIF('S3 Regular Season'!A:A, A11, 'S3 Regular Season'!D:D) + SUMIF('S3 Regular Season'!K:K, A11, 'S3 Regular Season'!N:N) -> 0 | E11: =SUMIF('S3 Regular Season'!A:A, A11, 'S3 Regular Season'!F:F) + SUMIF('S3 Regular Season'!K:K, A11, 'S3 Regular Season'!P:P) -> 0 | F11: =IFERROR(SUMIF(S3_Stats[4], A11, S3_Stats[Total Damage]) / SUMIF(S3_Game_Stats[Name], A11, S3_Game_Stats[Rounds Played]), 0) -> 0 | G11: =SUMIF(S3_Stats[4], A11, S3_Stats[Kills]) - SUMIF(S3_Stats[4], A11, S3_Stats[Deaths]) -> 0 | M11: Best ADR | N11: {=INDIRECT("A"&MATCH(MAX(S3_Stats[ADR]), S3_Stats[ADR], 0)+1)} -> Adam | O11: =MAX(S3_Stats[ADR]) -> 0
A12: Steve | B12: =SUMIF('S3 Regular Season'!A:A, A12, 'S3 Regular Season'!B:B) + SUMIF('S3 Regular Season'!K:K, A12, 'S3 Regular Season'!L:L) -> 0 | C12: =SUMIF('S3 Regular Season'!A:A, A12, 'S3 Regular Season'!C:C) + SUMIF('S3 Regular Season'!K:K, A12, 'S3 Regular Season'!M:M) -> 0 | D12: =SUMIF('S3 Regular Season'!A:A, A12, 'S3 Regular Season'!D:D) + SUMIF('S3 Regular Season'!K:K, A12, 'S3 Regular Season'!N:N) -> 0 | E12: =SUMIF('S3 Regular Season'!A:A, A12, 'S3 Regular Season'!F:F) + SUMIF('S3 Regular Season'!K:K, A12, 'S3 Regular Season'!P:P) -> 0 | F12: =IFERROR(SUMIF(S3_Stats[4], A12, S3_Stats[Total Damage]) / SUMIF(S3_Game_Stats[Name], A12, S3_Game_Stats[Rounds Played]), 0) -> 0 | G12: =SUMIF(S3_Stats[4], A12, S3_Stats[Kills]) - SUMIF(S3_Stats[4], A12, S3_Stats[Deaths]) -> 0 | M12: Longest Avg Game | N12: {=INDIRECT("A"&MATCH(MAX(S3_Avg_Game_Stats[Rounds/Game]), S3_Avg_Game_Stats[Rounds/Game], 0)+38)} -> #N/A | O12: =MAX(S3_Avg_Game_Stats[Rounds/Game]) -> 0
A13: Tim | B13: =SUMIF('S3 Regular Season'!A:A, A13, 'S3 Regular Season'!B:B) + SUMIF('S3 Regular Season'!K:K, A13, 'S3 Regular Season'!L:L) -> 0 | C13: =SUMIF('S3 Regular Season'!A:A, A13, 'S3 Regular Season'!C:C) + SUMIF('S3 Regular Season'!K:K, A13, 'S3 Regular Season'!M:M) -> 0 | D13: =SUMIF('S3 Regular Season'!A:A, A13, 'S3 Regular Season'!D:D) + SUMIF('S3 Regular Season'!K:K, A13, 'S3 Regular Season'!N:N) -> 0 | E13: =SUMIF('S3 Regular Season'!A:A, A13, 'S3 Regular Season'!F:F) + SUMIF('S3 Regular Season'!K:K, A13, 'S3 Regular Season'!P:P) -> 0 | F13: =IFERROR(SUMIF(S3_Stats[4], A13, S3_Stats[Total Damage]) / SUMIF(S3_Game_Stats[Name], A13, S3_Game_Stats[Rounds Played]), 0) -> 0 | G13: =SUMIF(S3_Stats[4], A13, S3_Stats[Kills]) - SUMIF(S3_Stats[4], A13, S3_Stats[Deaths]) -> 0
A14: Zach | B14: =SUMIF('S3 Regular Season'!A:A, A14, 'S3 Regular Season'!B:B) + SUMIF('S3 Regular Season'!K:K, A14, 'S3 Regular Season'!L:L) -> 0 | C14: =SUMIF('S3 Regular Season'!A:A, A14, 'S3 Regular Season'!C:C) + SUMIF('S3 Regular Season'!K:K, A14, 'S3 Regular Season'!M:M) -> 0 | D14: =SUMIF('S3 Regular Season'!A:A, A14, 'S3 Regular Season'!D:D) + SUMIF('S3 Regular Season'!K:K, A14, 'S3 Regular Season'!N:N) -> 0 | E14: =SUMIF('S3 Regular Season'!A:A, A14, 'S3 Regular Season'!F:F) + SUMIF('S3 Regular Season'!K:K, A14, 'S3 Regular Season'!P:P) -> 0 | F14: =IFERROR(SUMIF(S3_Stats[4], A14, S3_Stats[Total Damage]) / SUMIF(S3_Game_Stats[Name], A14, S3_Game_Stats[Rounds Played]), 0) -> 0 | G14: =SUMIF(S3_Stats[4], A14, S3_Stats[Kills]) - SUMIF(S3_Stats[4], A14, S3_Stats[Deaths]) -> 0
A17: Name | B17: K/D | C17: Dmg/Kill | D17: Kills/Round | E17: Assists/Round | F17: Deaths/Round | G17: Kills/Win | H17: Deaths/Win | I17: Kills/Loss | J17: Deaths/Loss
A18: Adam | B18: =IFERROR(SUMIF(S3_Stats[4], A18, S3_Stats[Kills]) / SUMIF(S3_Stats[4], A18, S3_Stats[Deaths]),"") | C18: =IFERROR(SUMIF(S3_Stats[4], A18, S3_Stats[Total Damage]) / SUMIF(S3_Stats[4], A18, S3_Stats[Kills]),"") | D18: =IFERROR(SUMIF(S3_Stats[4], A18, S3_Stats[Kills]) / SUMIF(S3_Game_Stats[Name], A18, S3_Game_Stats[Rounds Played]),"") | E18: =IFERROR(SUMIF(S3_Stats[4], A18, S3_Stats[Assists]) / SUMIF(S3_Game_Stats[Name], A18, S3_Game_Stats[Rounds Played]),"") | F18: =IFERROR(SUMIF(S3_Stats[4], A18, S3_Stats[Deaths]) / SUMIF(S3_Game_Stats[Name], A18, S3_Game_Stats[Rounds Played]),"") | G18: =IFERROR((SUMIFS('S3 Regular Season'!B:B, 'S3 Regular Season'!A:A, A18, 'S3 Regular Season'!I:I, 1) + SUMIFS('S3 Regular Season'!L:L, 'S3 Regular Season'!K:K, A18, 'S3 Regular Season'!S:S, 1)) / SUMIF(S3_Game_Stats[Name], A18, S3_Game_Stats[Wins]),"") | H18: =IFERROR((SUMIFS('S3 Regular Season'!D:D, 'S3 Regular Season'!A:A, A18, 'S3 Regular Season'!I:I, 1) + SUMIFS('S3 Regular Season'!N:N, 'S3 Regular Season'!K:K, A18, 'S3 Regular Season'!S:S, 1)) / SUMIF(S3_Game_Stats[Name], A18, S3_Game_Stats[Wins]),"") | I18: =IFERROR((SUMIFS('S3 Regular Season'!B:B, 'S3 Regular Season'!A:A, A18, 'S3 Regular Season'!I:I, 0) + SUMIFS('S3 Regular Season'!L:L, 'S3 Regular Season'!K:K, A18, 'S3 Regular Season'!S:S, 0)) / SUMIF(S3_Game_Stats[Name], A18, S3_Game_Stats[Losses]),"") | J18: =IFERROR((SUMIFS('S3 Regular Season'!D:D, 'S3 Regular Season'!A:A, A18, 'S3 Regular Season'!I:I, 0) + SUMIFS('S3 Regular Season'!N:N, 'S3 Regular Season'!K:K, A18, 'S3 Regular Season'!S:S, 0)) / SUMIF(S3_Game_Stats[Name], A18, S3_Game_Stats[Losses]),"")
A19: Andrew | B19: =IFERROR(SUMIF(S3_Stats[4], A19, S3_Stats[Kills]) / SUMIF(S3_Stats[4], A19, S3_Stats[Deaths]),"") | C19: =IFERROR(SUMIF(S3_Stats[4], A19, S3_Stats[Total Damage]) / SUMIF(S3_Stats[4], A19, S3_Stats[Kills]),"") | D19: =IFERROR(SUMIF(S3_Stats[4], A19, S3_Stats[Kills]) / SUMIF(S3_Game_Stats[Name], A19, S3_Game_Stats[Rounds Played]),"") | E19: =IFERROR(SUMIF(S3_Stats[4], A19, S3_Stats[Assists]) / SUMIF(S3_Game_Stats[Name], A19, S3_Game_Stats[Rounds Played]),"") | F19: =IFERROR(SUMIF(S3_Stats[4], A19, S3_Stats[Deaths]) / SUMIF(S3_Game_Stats[Name], A19, S3_Game_Stats[Rounds Played]),"") | G19: =IFERROR((SUMIFS('S3 Regular Season'!B:B, 'S3 Regular Season'!A:A, A19, 'S3 Regular Season'!I:I, 1) + SUMIFS('S3 Regular Season'!L:L, 'S3 Regular Season'!K:K, A19, 'S3 Regular Season'!S:S, 1)) / SUMIF(S3_Game_Stats[Name], A19, S3_Game_Stats[Wins]),"") | H19: =IFERROR((SUMIFS('S3 Regular Season'!D:D, 'S3 Regular Season'!A:A, A19, 'S3 Regular Season'!I:I, 1) + SUMIFS('S3 Regular Season'!N:N, 'S3 Regular Season'!K:K, A19, 'S3 Regular Season'!S:S, 1)) / SUMIF(S3_Game_Stats[Name], A19, S3_Game_Stats[Wins]),"") | I19: =IFERROR((SUMIFS('S3 Regular Season'!B:B, 'S3 Regular Season'!A:A, A19, 'S3 Regular Season'!I:I, 0) + SUMIFS('S3 Regular Season'!L:L, 'S3 Regular Season'!K:K, A19, 'S3 Regular Season'!S:S, 0)) / SUMIF(S3_Game_Stats[Name], A19, S3_Game_Stats[Losses]),"") | J19: =IFERROR((SUMIFS('S3 Regular Season'!D:D, 'S3 Regular Season'!A:A, A19, 'S3 Regular Season'!I:I, 0) + SUMIFS('S3 Regular Season'!N:N, 'S3 Regular Season'!K:K, A19, 'S3 Regular Season'!S:S, 0)) / SUMIF(S3_Game_Stats[Name], A19, S3_Game_Stats[Losses]),"")
A20: Brian | B20: =IFERROR(SUMIF(S3_Stats[4], A20, S3_Stats[Kills]) / SUMIF(S3_Stats[4], A20, S3_Stats[Deaths]),"") | C20: =IFERROR(SUMIF(S3_Stats[4], A20, S3_Stats[Total Damage]) / SUMIF(S3_Stats[4], A20, S3_Stats[Kills]),"") | D20: =IFERROR(SUMIF(S3_Stats[4], A20, S3_Stats[Kills]) / SUMIF(S3_Game_Stats[Name], A20, S3_Game_Stats[Rounds Played]),"") | E20: =IFERROR(SUMIF(S3_Stats[4], A20, S3_Stats[Assists]) / SUMIF(S3_Game_Stats[Name], A20, S3_Game_Stats[Rounds Played]),"") | F20: =IFERROR(SUMIF(S3_Stats[4], A20, S3_Stats[Deaths]) / SUMIF(S3_Game_Stats[Name], A20, S3_Game_Stats[Rounds Played]),"") | G20: =IFERROR((SUMIFS('S3 Regular Season'!B:B, 'S3 Regular Season'!A:A, A20, 'S3 Regular Season'!I:I, 1) + SUMIFS('S3 Regular Season'!L:L, 'S3 Regular Season'!K:K, A20, 'S3 Regular Season'!S:S, 1)) / SUMIF(S3_Game_Stats[Name], A20, S3_Game_Stats[Wins]),"") | H20: =IFERROR((SUMIFS('S3 Regular Season'!D:D, 'S3 Regular Season'!A:A, A20, 'S3 Regular Season'!I:I, 1) + SUMIFS('S3 Regular Season'!N:N, 'S3 Regular Season'!K:K, A20, 'S3 Regular Season'!S:S, 1)) / SUMIF(S3_Game_Stats[Name], A20, S3_Game_Stats[Wins]),"") | I20: =IFERROR((SUMIFS('S3 Regular Season'!B:B, 'S3 Regular Season'!A:A, A20, 'S3 Regular Season'!I:I, 0) + SUMIFS('S3 Regular Season'!L:L, 'S3 Regular Season'!K:K, A20, 'S3 Regular Season'!S:S, 0)) / SUMIF(S3_Game_Stats[Name], A20, S3_Game_Stats[Losses]),"") | J20: =IFERROR((SUMIFS('S3 Regular Season'!D:D, 'S3 Regular Season'!A:A, A20, 'S3 Regular Season'!I:I, 0) + SUMIFS('S3 Regular Season'!N:N, 'S3 Regular Season'!K:K, A20, 'S3 Regular Season'!S:S, 0)) / SUMIF(S3_Game_Stats[Name], A20, S3_Game_Stats[Losses]),"")
A21: Dan | B21: =IFERROR(SUMIF(S3_Stats[4], A21, S3_Stats[Kills]) / SUMIF(S3_Stats[4], A21, S3_Stats[Deaths]),"") | C21: =IFERROR(SUMIF(S3_Stats[4], A21, S3_Stats[Total Damage]) / SUMIF(S3_Stats[4], A21, S3_Stats[Kills]),"") | D21: =IFERROR(SUMIF(S3_Stats[4], A21, S3_Stats[Kills]) / SUMIF(S3_Game_Stats[Name], A21, S3_Game_Stats[Rounds Played]),"") | E21: =IFERROR(SUMIF(S3_Stats[4], A21, S3_Stats[Assists]) / SUMIF(S3_Game_Stats[Name], A21, S3_Game_Stats[Rounds Played]),"") | F21: =IFERROR(SUMIF(S3_Stats[4], A21, S3_Stats[Deaths]) / SUMIF(S3_Game_Stats[Name], A21, S3_Game_Stats[Rounds Played]),"") | G21: =IFERROR((SUMIFS('S3 Regular Season'!B:B, 'S3 Regular Season'!A:A, A21, 'S3 Regular Season'!I:I, 1) + SUMIFS('S3 Regular Season'!L:L, 'S3 Regular Season'!K:K, A21, 'S3 Regular Season'!S:S, 1)) / SUMIF(S3_Game_Stats[Name], A21, S3_Game_Stats[Wins]),"") | H21: =IFERROR((SUMIFS('S3 Regular Season'!D:D, 'S3 Regular Season'!A:A, A21, 'S3 Regular Season'!I:I, 1) + SUMIFS('S3 Regular Season'!N:N, 'S3 Regular Season'!K:K, A21, 'S3 Regular Season'!S:S, 1)) / SUMIF(S3_Game_Stats[Name], A21, S3_Game_Stats[Wins]),"") | I21: =IFERROR((SUMIFS('S3 Regular Season'!B:B, 'S3 Regular Season'!A:A, A21, 'S3 Regular Season'!I:I, 0) + SUMIFS('S3 Regular Season'!L:L, 'S3 Regular Season'!K:K, A21, 'S3 Regular Season'!S:S, 0)) / SUMIF(S3_Game_Stats[Name], A21, S3_Game_Stats[Losses]),"") | J21: =IFERROR((SUMIFS('S3 Regular Season'!D:D, 'S3 Regular Season'!A:A, A21, 'S3 Regular Season'!I:I, 0) + SUMIFS('S3 Regular Season'!N:N, 'S3 Regular Season'!K:K, A21, 'S3 Regular Season'!S:S, 0)) / SUMIF(S3_Game_Stats[Name], A21, S3_Game_Stats[Losses]),"")
A22: Emanuel | B22: =IFERROR(SUMIF(S3_Stats[4], A22, S3_Stats[Kills]) / SUMIF(S3_Stats[4], A22, S3_Stats[Deaths]),"") | C22: =IFERROR(SUMIF(S3_Stats[4], A22, S3_Stats[Total Damage]) / SUMIF(S3_Stats[4], A22, S3_Stats[Kills]),"") | D22: =IFERROR(SUMIF(S3_Stats[4], A22, S3_Stats[Kills]) / SUMIF(S3_Game_Stats[Name], A22, S3_Game_Stats[Rounds Played]),"") | E22: =IFERROR(SUMIF(S3_Stats[4], A22, S3_Stats[Assists]) / SUMIF(S3_Game_Stats[Name], A22, S3_Game_Stats[Rounds Played]),"") | F22: =IFERROR(SUMIF(S3_Stats[4], A22, S3_Stats[Deaths]) / SUMIF(S3_Game_Stats[Name], A22, S3_Game_Stats[Rounds Played]),"") | G22: =IFERROR((SUMIFS('S3 Regular Season'!B:B, 'S3 Regular Season'!A:A, A22, 'S3 Regular Season'!I:I, 1) + SUMIFS('S3 Regular Season'!L:L, 'S3 Regular Season'!K:K, A22, 'S3 Regular Season'!S:S, 1)) / SUMIF(S3_Game_Stats[Name], A22, S3_Game_Stats[Wins]),"") | H22: =IFERROR((SUMIFS('S3 Regular Season'!D:D, 'S3 Regular Season'!A:A, A22, 'S3 Regular Season'!I:I, 1) + SUMIFS('S3 Regular Season'!N:N, 'S3 Regular Season'!K:K, A22, 'S3 Regular Season'!S:S, 1)) / SUMIF(S3_Game_Stats[Name], A22, S3_Game_Stats[Wins]),"") | I22: =IFERROR((SUMIFS('S3 Regular Season'!B:B, 'S3 Regular Season'!A:A, A22, 'S3 Regular Season'!I:I, 0) + SUMIFS('S3 Regular Season'!L:L, 'S3 Regular Season'!K:K, A22, 'S3 Regular Season'!S:S, 0)) / SUMIF(S3_Game_Stats[Name], A22, S3_Game_Stats[Losses]),"") | J22: =IFERROR((SUMIFS('S3 Regular Season'!D:D, 'S3 Regular Season'!A:A, A22, 'S3 Regular Season'!I:I, 0) + SUMIFS('S3 Regular Season'!N:N, 'S3 Regular Season'!K:K, A22, 'S3 Regular Season'!S:S, 0)) / SUMIF(S3_Game_Stats[Name], A22, S3_Game_Stats[Losses]),"")
A23: Eric | B23: =IFERROR(SUMIF(S3_Stats[4], A23, S3_Stats[Kills]) / SUMIF(S3_Stats[4], A23, S3_Stats[Deaths]),"") | C23: =IFERROR(SUMIF(S3_Stats[4], A23, S3_Stats[Total Damage]) / SUMIF(S3_Stats[4], A23, S3_Stats[Kills]),"") | D23: =IFERROR(SUMIF(S3_Stats[4], A23, S3_Stats[Kills]) / SUMIF(S3_Game_Stats[Name], A23, S3_Game_Stats[Rounds Played]),"") | E23: =IFERROR(SUMIF(S3_Stats[4], A23, S3_Stats[Assists]) / SUMIF(S3_Game_Stats[Name], A23, S3_Game_Stats[Rounds Played]),"") | F23: =IFERROR(SUMIF(S3_Stats[4], A23, S3_Stats[Deaths]) / SUMIF(S3_Game_Stats[Name], A23, S3_Game_Stats[Rounds Played]),"") | G23: =IFERROR((SUMIFS('S3 Regular Season'!B:B, 'S3 Regular Season'!A:A, A23, 'S3 Regular Season'!I:I, 1) + SUMIFS('S3 Regular Season'!L:L, 'S3 Regular Season'!K:K, A23, 'S3 Regular Season'!S:S, 1)) / SUMIF(S3_Game_Stats[Name], A23, S3_Game_Stats[Wins]),"") | H23: =IFERROR((SUMIFS('S3 Regular Season'!D:D, 'S3 Regular Season'!A:A, A23, 'S3 Regular Season'!I:I, 1) + SUMIFS('S3 Regular Season'!N:N, 'S3 Regular Season'!K:K, A23, 'S3 Regular Season'!S:S, 1)) / SUMIF(S3_Game_Stats[Name], A23, S3_Game_Stats[Wins]),"") | I23: =IFERROR((SUMIFS('S3 Regular Season'!B:B, 'S3 Regular Season'!A:A, A23, 'S3 Regular Season'!I:I, 0) + SUMIFS('S3 Regular Season'!L:L, 'S3 Regular Season'!K:K, A23, 'S3 Regular Season'!S:S, 0)) / SUMIF(S3_Game_Stats[Name], A23, S3_Game_Stats[Losses]),"") | J23: =IFERROR((SUMIFS('S3 Regular Season'!D:D, 'S3 Regular Season'!A:A, A23, 'S3 Regular Season'!I:I, 0) + SUMIFS('S3 Regular Season'!N:N, 'S3 Regular Season'!K:K, A23, 'S3 Regular Season'!S:S, 0)) / SUMIF(S3_Game_Stats[Name], A23, S3_Game_Stats[Losses]),"")
A24: Fred | B24: =IFERROR(SUMIF(S3_Stats[4], A24, S3_Stats[Kills]) / SUMIF(S3_Stats[4], A24, S3_Stats[Deaths]),"") | C24: =IFERROR(SUMIF(S3_Stats[4], A24, S3_Stats[Total Damage]) / SUMIF(S3_Stats[4], A24, S3_Stats[Kills]),"") | D24: =IFERROR(SUMIF(S3_Stats[4], A24, S3_Stats[Kills]) / SUMIF(S3_Game_Stats[Name], A24, S3_Game_Stats[Rounds Played]),"") | E24: =IFERROR(SUMIF(S3_Stats[4], A24, S3_Stats[Assists]) / SUMIF(S3_Game_Stats[Name], A24, S3_Game_Stats[Rounds Played]),"") | F24: =IFERROR(SUMIF(S3_Stats[4], A24, S3_Stats[Deaths]) / SUMIF(S3_Game_Stats[Name], A24, S3_Game_Stats[Rounds Played]),"") | G24: =IFERROR((SUMIFS('S3 Regular Season'!B:B, 'S3 Regular Season'!A:A, A24, 'S3 Regular Season'!I:I, 1) + SUMIFS('S3 Regular Season'!L:L, 'S3 Regular Season'!K:K, A24, 'S3 Regular Season'!S:S, 1)) / SUMIF(S3_Game_Stats[Name], A24, S3_Game_Stats[Wins]),"") | H24: =IFERROR((SUMIFS('S3 Regular Season'!D:D, 'S3 Regular Season'!A:A, A24, 'S3 Regular Season'!I:I, 1) + SUMIFS('S3 Regular Season'!N:N, 'S3 Regular Season'!K:K, A24, 'S3 Regular Season'!S:S, 1)) / SUMIF(S3_Game_Stats[Name], A24, S3_Game_Stats[Wins]),"") | I24: =IFERROR((SUMIFS('S3 Regular Season'!B:B, 'S3 Regular Season'!A:A, A24, 'S3 Regular Season'!I:I, 0) + SUMIFS('S3 Regular Season'!L:L, 'S3 Regular Season'!K:K, A24, 'S3 Regular Season'!S:S, 0)) / SUMIF(S3_Game_Stats[Name], A24, S3_Game_Stats[Losses]),"") | J24: =IFERROR((SUMIFS('S3 Regular Season'!D:D, 'S3 Regular Season'!A:A, A24, 'S3 Regular Season'!I:I, 0) + SUMIFS('S3 Regular Season'!N:N, 'S3 Regular Season'!K:K, A24, 'S3 Regular Season'!S:S, 0)) / SUMIF(S3_Game_Stats[Name], A24, S3_Game_Stats[Losses]),"")
A25: Kevin | B25: =IFERROR(SUMIF(S3_Stats[4], A25, S3_Stats[Kills]) / SUMIF(S3_Stats[4], A25, S3_Stats[Deaths]),"") | C25: =IFERROR(SUMIF(S3_Stats[4], A25, S3_Stats[Total Damage]) / SUMIF(S3_Stats[4], A25, S3_Stats[Kills]),"") | D25: =IFERROR(SUMIF(S3_Stats[4], A25, S3_Stats[Kills]) / SUMIF(S3_Game_Stats[Name], A25, S3_Game_Stats[Rounds Played]),"") | E25: =IFERROR(SUMIF(S3_Stats[4], A25, S3_Stats[Assists]) / SUMIF(S3_Game_Stats[Name], A25, S3_Game_Stats[Rounds Played]),"") | F25: =IFERROR(SUMIF(S3_Stats[4], A25, S3_Stats[Deaths]) / SUMIF(S3_Game_Stats[Name], A25, S3_Game_Stats[Rounds Played]),"") | G25: =IFERROR((SUMIFS('S3 Regular Season'!B:B, 'S3 Regular Season'!A:A, A25, 'S3 Regular Season'!I:I, 1) + SUMIFS('S3 Regular Season'!L:L, 'S3 Regular Season'!K:K, A25, 'S3 Regular Season'!S:S, 1)) / SUMIF(S3_Game_Stats[Name], A25, S3_Game_Stats[Wins]),"") | H25: =IFERROR((SUMIFS('S3 Regular Season'!D:D, 'S3 Regular Season'!A:A, A25, 'S3 Regular Season'!I:I, 1) + SUMIFS('S3 Regular Season'!N:N, 'S3 Regular Season'!K:K, A25, 'S3 Regular Season'!S:S, 1)) / SUMIF(S3_Game_Stats[Name], A25, S3_Game_Stats[Wins]),"") | I25: =IFERROR((SUMIFS('S3 Regular Season'!B:B, 'S3 Regular Season'!A:A, A25, 'S3 Regular Season'!I:I, 0) + SUMIFS('S3 Regular Season'!L:L, 'S3 Regular Season'!K:K, A25, 'S3 Regular Season'!S:S, 0)) / SUMIF(S3_Game_Stats[Name], A25, S3_Game_Stats[Losses]),"") | J25: =IFERROR((SUMIFS('S3 Regular Season'!D:D, 'S3 Regular Season'!A:A, A25, 'S3 Regular Season'!I:I, 0) + SUMIFS('S3 Regular Season'!N:N, 'S3 Regular Season'!K:K, A25, 'S3 Regular Season'!S:S, 0)) / SUMIF(S3_Game_Stats[Name], A25, S3_Game_Stats[Losses]),"")
A26: Michael | B26: =IFERROR(SUMIF(S3_Stats[4], A26, S3_Stats[Kills]) / SUMIF(S3_Stats[4], A26, S3_Stats[Deaths]),"") | C26: =IFERROR(SUMIF(S3_Stats[4], A26, S3_Stats[Total Damage]) / SUMIF(S3_Stats[4], A26, S3_Stats[Kills]),"") | D26: =IFERROR(SUMIF(S3_Stats[4], A26, S3_Stats[Kills]) / SUMIF(S3_Game_Stats[Name], A26, S3_Game_Stats[Rounds Played]),"") | E26: =IFERROR(SUMIF(S3_Stats[4], A26, S3_Stats[Assists]) / SUMIF(S3_Game_Stats[Name], A26, S3_Game_Stats[Rounds Played]),"") | F26: =IFERROR(SUMIF(S3_Stats[4], A26, S3_Stats[Deaths]) / SUMIF(S3_Game_Stats[Name], A26, S3_Game_Stats[Rounds Played]),"") | G26: =IFERROR((SUMIFS('S3 Regular Season'!B:B, 'S3 Regular Season'!A:A, A26, 'S3 Regular Season'!I:I, 1) + SUMIFS('S3 Regular Season'!L:L, 'S3 Regular Season'!K:K, A26, 'S3 Regular Season'!S:S, 1)) / SUMIF(S3_Game_Stats[Name], A26, S3_Game_Stats[Wins]),"") | H26: =IFERROR((SUMIFS('S3 Regular Season'!D:D, 'S3 Regular Season'!A:A, A26, 'S3 Regular Season'!I:I, 1) + SUMIFS('S3 Regular Season'!N:N, 'S3 Regular Season'!K:K, A26, 'S3 Regular Season'!S:S, 1)) / SUMIF(S3_Game_Stats[Name], A26, S3_Game_Stats[Wins]),"") | I26: =IFERROR((SUMIFS('S3 Regular Season'!B:B, 'S3 Regular Season'!A:A, A26, 'S3 Regular Season'!I:I, 0) + SUMIFS('S3 Regular Season'!L:L, 'S3 Regular Season'!K:K, A26, 'S3 Regular Season'!S:S, 0)) / SUMIF(S3_Game_Stats[Name], A26, S3_Game_Stats[Losses]),"") | J26: =IFERROR((SUMIFS('S3 Regular Season'!D:D, 'S3 Regular Season'!A:A, A26, 'S3 Regular Season'!I:I, 0) + SUMIFS('S3 Regular Season'!N:N, 'S3 Regular Season'!K:K, A26, 'S3 Regular Season'!S:S, 0)) / SUMIF(S3_Game_Stats[Name], A26, S3_Game_Stats[Losses]),"")
A27: Sean | B27: =IFERROR(SUMIF(S3_Stats[4], A27, S3_Stats[Kills]) / SUMIF(S3_Stats[4], A27, S3_Stats[Deaths]),"") | C27: =IFERROR(SUMIF(S3_Stats[4], A27, S3_Stats[Total Damage]) / SUMIF(S3_Stats[4], A27, S3_Stats[Kills]),"") | D27: =IFERROR(SUMIF(S3_Stats[4], A27, S3_Stats[Kills]) / SUMIF(S3_Game_Stats[Name], A27, S3_Game_Stats[Rounds Played]),"") | E27: =IFERROR(SUMIF(S3_Stats[4], A27, S3_Stats[Assists]) / SUMIF(S3_Game_Stats[Name], A27, S3_Game_Stats[Rounds Played]),"") | F27: =IFERROR(SUMIF(S3_Stats[4], A27, S3_Stats[Deaths]) / SUMIF(S3_Game_Stats[Name], A27, S3_Game_Stats[Rounds Played]),"") | G27: =IFERROR((SUMIFS('S3 Regular Season'!B:B, 'S3 Regular Season'!A:A, A27, 'S3 Regular Season'!I:I, 1) + SUMIFS('S3 Regular Season'!L:L, 'S3 Regular Season'!K:K, A27, 'S3 Regular Season'!S:S, 1)) / SUMIF(S3_Game_Stats[Name], A27, S3_Game_Stats[Wins]),"") | H27: =IFERROR((SUMIFS('S3 Regular Season'!D:D, 'S3 Regular Season'!A:A, A27, 'S3 Regular Season'!I:I, 1) + SUMIFS('S3 Regular Season'!N:N, 'S3 Regular Season'!K:K, A27, 'S3 Regular Season'!S:S, 1)) / SUMIF(S3_Game_Stats[Name], A27, S3_Game_Stats[Wins]),"") | I27: =IFERROR((SUMIFS('S3 Regular Season'!B:B, 'S3 Regular Season'!A:A, A27, 'S3 Regular Season'!I:I, 0) + SUMIFS('S3 Regular Season'!L:L, 'S3 Regular Season'!K:K, A27, 'S3 Regular Season'!S:S, 0)) / SUMIF(S3_Game_Stats[Name], A27, S3_Game_Stats[Losses]),"") | J27: =IFERROR((SUMIFS('S3 Regular Season'!D:D, 'S3 Regular Season'!A:A, A27, 'S3 Regular Season'!I:I, 0) + SUMIFS('S3 Regular Season'!N:N, 'S3 Regular Season'!K:K, A27, 'S3 Regular Season'!S:S, 0)) / SUMIF(S3_Game_Stats[Name], A27, S3_Game_Stats[Losses]),"")
A28: Steve | B28: =IFERROR(SUMIF(S3_Stats[4], A28, S3_Stats[Kills]) / SUMIF(S3_Stats[4], A28, S3_Stats[Deaths]),"") | C28: =IFERROR(SUMIF(S3_Stats[4], A28, S3_Stats[Total Damage]) / SUMIF(S3_Stats[4], A28, S3_Stats[Kills]),"") | D28: =IFERROR(SUMIF(S3_Stats[4], A28, S3_Stats[Kills]) / SUMIF(S3_Game_Stats[Name], A28, S3_Game_Stats[Rounds Played]),"") | E28: =IFERROR(SUMIF(S3_Stats[4], A28, S3_Stats[Assists]) / SUMIF(S3_Game_Stats[Name], A28, S3_Game_Stats[Rounds Played]),"") | F28: =IFERROR(SUMIF(S3_Stats[4], A28, S3_Stats[Deaths]) / SUMIF(S3_Game_Stats[Name], A28, S3_Game_Stats[Rounds Played]),"") | G28: =IFERROR((SUMIFS('S3 Regular Season'!B:B, 'S3 Regular Season'!A:A, A28, 'S3 Regular Season'!I:I, 1) + SUMIFS('S3 Regular Season'!L:L, 'S3 Regular Season'!K:K, A28, 'S3 Regular Season'!S:S, 1)) / SUMIF(S3_Game_Stats[Name], A28, S3_Game_Stats[Wins]),"") | H28: =IFERROR((SUMIFS('S3 Regular Season'!D:D, 'S3 Regular Season'!A:A, A28, 'S3 Regular Season'!I:I, 1) + SUMIFS('S3 Regular Season'!N:N, 'S3 Regular Season'!K:K, A28, 'S3 Regular Season'!S:S, 1)) / SUMIF(S3_Game_Stats[Name], A28, S3_Game_Stats[Wins]),"") | I28: =IFERROR((SUMIFS('S3 Regular Season'!B:B, 'S3 Regular Season'!A:A, A28, 'S3 Regular Season'!I:I, 0) + SUMIFS('S3 Regular Season'!L:L, 'S3 Regular Season'!K:K, A28, 'S3 Regular Season'!S:S, 0)) / SUMIF(S3_Game_Stats[Name], A28, S3_Game_Stats[Losses]),"") | J28: =IFERROR((SUMIFS('S3 Regular Season'!D:D, 'S3 Regular Season'!A:A, A28, 'S3 Regular Season'!I:I, 0) + SUMIFS('S3 Regular Season'!N:N, 'S3 Regular Season'!K:K, A28, 'S3 Regular Season'!S:S, 0)) / SUMIF(S3_Game_Stats[Name], A28, S3_Game_Stats[Losses]),"")
A29: Tim | B29: =IFERROR(SUMIF(S3_Stats[4], A29, S3_Stats[Kills]) / SUMIF(S3_Stats[4], A29, S3_Stats[Deaths]),"") | C29: =IFERROR(SUMIF(S3_Stats[4], A29, S3_Stats[Total Damage]) / SUMIF(S3_Stats[4], A29, S3_Stats[Kills]),"") | D29: =IFERROR(SUMIF(S3_Stats[4], A29, S3_Stats[Kills]) / SUMIF(S3_Game_Stats[Name], A29, S3_Game_Stats[Rounds Played]),"") | E29: =IFERROR(SUMIF(S3_Stats[4], A29, S3_Stats[Assists]) / SUMIF(S3_Game_Stats[Name], A29, S3_Game_Stats[Rounds Played]),"") | F29: =IFERROR(SUMIF(S3_Stats[4], A29, S3_Stats[Deaths]) / SUMIF(S3_Game_Stats[Name], A29, S3_Game_Stats[Rounds Played]),"") | G29: =IFERROR((SUMIFS('S3 Regular Season'!B:B, 'S3 Regular Season'!A:A, A29, 'S3 Regular Season'!I:I, 1) + SUMIFS('S3 Regular Season'!L:L, 'S3 Regular Season'!K:K, A29, 'S3 Regular Season'!S:S, 1)) / SUMIF(S3_Game_Stats[Name], A29, S3_Game_Stats[Wins]),"") | H29: =IFERROR((SUMIFS('S3 Regular Season'!D:D, 'S3 Regular Season'!A:A, A29, 'S3 Regular Season'!I:I, 1) + SUMIFS('S3 Regular Season'!N:N, 'S3 Regular Season'!K:K, A29, 'S3 Regular Season'!S:S, 1)) / SUMIF(S3_Game_Stats[Name], A29, S3_Game_Stats[Wins]),"") | I29: =IFERROR((SUMIFS('S3 Regular Season'!B:B, 'S3 Regular Season'!A:A, A29, 'S3 Regular Season'!I:I, 0) + SUMIFS('S3 Regular Season'!L:L, 'S3 Regular Season'!K:K, A29, 'S3 Regular Season'!S:S, 0)) / SUMIF(S3_Game_Stats[Name], A29, S3_Game_Stats[Losses]),"") | J29: =IFERROR((SUMIFS('S3 Regular Season'!D:D, 'S3 Regular Season'!A:A, A29, 'S3 Regular Season'!I:I, 0) + SUMIFS('S3 Regular Season'!N:N, 'S3 Regular Season'!K:K, A29, 'S3 Regular Season'!S:S, 0)) / SUMIF(S3_Game_Stats[Name], A29, S3_Game_Stats[Losses]),"")
A30: Zach | B30: =IFERROR(SUMIF(S3_Stats[4], A30, S3_Stats[Kills]) / SUMIF(S3_Stats[4], A30, S3_Stats[Deaths]),"") | C30: =IFERROR(SUMIF(S3_Stats[4], A30, S3_Stats[Total Damage]) / SUMIF(S3_Stats[4], A30, S3_Stats[Kills]),"") | D30: =IFERROR(SUMIF(S3_Stats[4], A30, S3_Stats[Kills]) / SUMIF(S3_Game_Stats[Name], A30, S3_Game_Stats[Rounds Played]),"") | E30: =IFERROR(SUMIF(S3_Stats[4], A30, S3_Stats[Assists]) / SUMIF(S3_Game_Stats[Name], A30, S3_Game_Stats[Rounds Played]),"") | F30: =IFERROR(SUMIF(S3_Stats[4], A30, S3_Stats[Deaths]) / SUMIF(S3_Game_Stats[Name], A30, S3_Game_Stats[Rounds Played]),"") | G30: =IFERROR((SUMIFS('S3 Regular Season'!B:B, 'S3 Regular Season'!A:A, A30, 'S3 Regular Season'!I:I, 1) + SUMIFS('S3 Regular Season'!L:L, 'S3 Regular Season'!K:K, A30, 'S3 Regular Season'!S:S, 1)) / SUMIF(S3_Game_Stats[Name], A30, S3_Game_Stats[Wins]),"") | H30: =IFERROR((SUMIFS('S3 Regular Season'!D:D, 'S3 Regular Season'!A:A, A30, 'S3 Regular Season'!I:I, 1) + SUMIFS('S3 Regular Season'!N:N, 'S3 Regular Season'!K:K, A30, 'S3 Regular Season'!S:S, 1)) / SUMIF(S3_Game_Stats[Name], A30, S3_Game_Stats[Wins]),"") | I30: =IFERROR((SUMIFS('S3 Regular Season'!B:B, 'S3 Regular Season'!A:A, A30, 'S3 Regular Season'!I:I, 0) + SUMIFS('S3 Regular Season'!L:L, 'S3 Regular Season'!K:K, A30, 'S3 Regular Season'!S:S, 0)) / SUMIF(S3_Game_Stats[Name], A30, S3_Game_Stats[Losses]),"") | J30: =IFERROR((SUMIFS('S3 Regular Season'!D:D, 'S3 Regular Season'!A:A, A30, 'S3 Regular Season'!I:I, 0) + SUMIFS('S3 Regular Season'!N:N, 'S3 Regular Season'!K:K, A30, 'S3 Regular Season'!S:S, 0)) / SUMIF(S3_Game_Stats[Name], A30, S3_Game_Stats[Losses]),"")
A33: Name | B33: Games | C33: Wins | D33: Losses | E33: WR % | F33: Round WR % | G33: Rounds Won | H33: Rounds Lost | I33: Rounds Played | L33: Place | M33: Player | N33: WR | O33: Round WR
A34: Adam | B34: =COUNTIFS('S3 Regular Season'!A:A, A34, 'S3 Regular Season'!I:I, "<>") + COUNTIFS('S3 Regular Season'!K:K, A34, 'S3 Regular Season'!S:S, "<>") -> 0 | C34: =SUMIF('S3 Regular Season'!A:A, A34, 'S3 Regular Season'!I:I) + SUMIF('S3 Regular Season'!K:K, A34, 'S3 Regular Season'!S:S) -> 0 | D34: =SUMIF(S3_Game_Stats[Name], A34, S3_Game_Stats[Games]) - SUMIF(S3_Game_Stats[Name], A34, S3_Game_Stats[Wins]) -> 0 | E34: =IFERROR(SUMIF(S3_Game_Stats[Name], A34, S3_Game_Stats[Wins]) / SUMIF(S3_Game_Stats[Name], A34, S3_Game_Stats[Games]),"") | F34: =IFERROR(SUMIF(S3_Game_Stats[Name], A34, S3_Game_Stats[Rounds Won]) / SUMIF(S3_Game_Stats[Name], A34, S3_Game_Stats[Rounds Played]),"") | G34: =SUMIF('S3 Regular Season'!A:A, A34, 'S3 Regular Season'!H:H) + SUMIF('S3 Regular Season'!K:K, A34, 'S3 Regular Season'!R:R) -> 0 | H34: =SUMIF(S3_Game_Stats[Name], A34, S3_Game_Stats[Rounds Played]) - SUMIF(S3_Game_Stats[Name], A34, S3_Game_Stats[Rounds Won]) -> 0 | I34: =SUMIF('S3 Regular Season'!A:A, A34, 'S3 Regular Season'!G:G) + SUMIF('S3 Regular Season'!K:K, A34, 'S3 Regular Season'!Q:Q) -> 0 | K34: 1st Round Bye | L34: 1 | M34: {=SORT(S3_Game_Stats[Name],S3_Game_Stats[WR %],false,S3_Game_Stats[Round WR %],false)} -> Adam | N34: {=SORT(S3_Game_Stats[WR %],S3_Game_Stats[WR %],false,S3_Game_Stats[Round WR %],false)} | O34: {=SORT(S3_Game_Stats[Round WR %],S3_Game_Stats[WR %],false,S3_Game_Stats[Round WR %],false)}
A35: Andrew | B35: =COUNTIFS('S3 Regular Season'!A:A, A35, 'S3 Regular Season'!I:I, "<>") + COUNTIFS('S3 Regular Season'!K:K, A35, 'S3 Regular Season'!S:S, "<>") -> 0 | C35: =SUMIF('S3 Regular Season'!A:A, A35, 'S3 Regular Season'!I:I) + SUMIF('S3 Regular Season'!K:K, A35, 'S3 Regular Season'!S:S) -> 0 | D35: =SUMIF(S3_Game_Stats[Name], A35, S3_Game_Stats[Games]) - SUMIF(S3_Game_Stats[Name], A35, S3_Game_Stats[Wins]) -> 0 | E35: =IFERROR(SUMIF(S3_Game_Stats[Name], A35, S3_Game_Stats[Wins]) / SUMIF(S3_Game_Stats[Name], A35, S3_Game_Stats[Games]),"") | F35: =IFERROR(SUMIF(S3_Game_Stats[Name], A35, S3_Game_Stats[Rounds Won]) / SUMIF(S3_Game_Stats[Name], A35, S3_Game_Stats[Rounds Played]),"") | G35: =SUMIF('S3 Regular Season'!A:A, A35, 'S3 Regular Season'!H:H) + SUMIF('S3 Regular Season'!K:K, A35, 'S3 Regular Season'!R:R) -> 0 | H35: =SUMIF(S3_Game_Stats[Name], A35, S3_Game_Stats[Rounds Played]) - SUMIF(S3_Game_Stats[Name], A35, S3_Game_Stats[Rounds Won]) -> 0 | I35: =SUMIF('S3 Regular Season'!A:A, A35, 'S3 Regular Season'!G:G) + SUMIF('S3 Regular Season'!K:K, A35, 'S3 Regular Season'!Q:Q) -> 0 | L35: 2 | M35: Andrew
A36: Brian | B36: =COUNTIFS('S3 Regular Season'!A:A, A36, 'S3 Regular Season'!I:I, "<>") + COUNTIFS('S3 Regular Season'!K:K, A36, 'S3 Regular Season'!S:S, "<>") -> 0 | C36: =SUMIF('S3 Regular Season'!A:A, A36, 'S3 Regular Season'!I:I) + SUMIF('S3 Regular Season'!K:K, A36, 'S3 Regular Season'!S:S) -> 0 | D36: =SUMIF(S3_Game_Stats[Name], A36, S3_Game_Stats[Games]) - SUMIF(S3_Game_Stats[Name], A36, S3_Game_Stats[Wins]) -> 0 | E36: =IFERROR(SUMIF(S3_Game_Stats[Name], A36, S3_Game_Stats[Wins]) / SUMIF(S3_Game_Stats[Name], A36, S3_Game_Stats[Games]),"") | F36: =IFERROR(SUMIF(S3_Game_Stats[Name], A36, S3_Game_Stats[Rounds Won]) / SUMIF(S3_Game_Stats[Name], A36, S3_Game_Stats[Rounds Played]),"") | G36: =SUMIF('S3 Regular Season'!A:A, A36, 'S3 Regular Season'!H:H) + SUMIF('S3 Regular Season'!K:K, A36, 'S3 Regular Season'!R:R) -> 0 | H36: =SUMIF(S3_Game_Stats[Name], A36, S3_Game_Stats[Rounds Played]) - SUMIF(S3_Game_Stats[Name], A36, S3_Game_Stats[Rounds Won]) -> 0 | I36: =SUMIF('S3 Regular Season'!A:A, A36, 'S3 Regular Season'!G:G) + SUMIF('S3 Regular Season'!K:K, A36, 'S3 Regular Season'!Q:Q) -> 0 | L36: 3 | M36: Brian
A37: Dan | B37: =COUNTIFS('S3 Regular Season'!A:A, A37, 'S3 Regular Season'!I:I, "<>") + COUNTIFS('S3 Regular Season'!K:K, A37, 'S3 Regular Season'!S:S, "<>") -> 0 | C37: =SUMIF('S3 Regular Season'!A:A, A37, 'S3 Regular Season'!I:I) + SUMIF('S3 Regular Season'!K:K, A37, 'S3 Regular Season'!S:S) -> 0 | D37: =SUMIF(S3_Game_Stats[Name], A37, S3_Game_Stats[Games]) - SUMIF(S3_Game_Stats[Name], A37, S3_Game_Stats[Wins]) -> 0 | E37: =IFERROR(SUMIF(S3_Game_Stats[Name], A37, S3_Game_Stats[Wins]) / SUMIF(S3_Game_Stats[Name], A37, S3_Game_Stats[Games]),"") | F37: =IFERROR(SUMIF(S3_Game_Stats[Name], A37, S3_Game_Stats[Rounds Won]) / SUMIF(S3_Game_Stats[Name], A37, S3_Game_Stats[Rounds Played]),"") | G37: =SUMIF('S3 Regular Season'!A:A, A37, 'S3 Regular Season'!H:H) + SUMIF('S3 Regular Season'!K:K, A37, 'S3 Regular Season'!R:R) -> 0 | H37: =SUMIF(S3_Game_Stats[Name], A37, S3_Game_Stats[Rounds Played]) - SUMIF(S3_Game_Stats[Name], A37, S3_Game_Stats[Rounds Won]) -> 0 | I37: =SUMIF('S3 Regular Season'!A:A, A37, 'S3 Regular Season'!G:G) + SUMIF('S3 Regular Season'!K:K, A37, 'S3 Regular Season'!Q:Q) -> 0 | L37: 4 | M37: Dan
A38: Emanuel | B38: =COUNTIFS('S3 Regular Season'!A:A, A38, 'S3 Regular Season'!I:I, "<>") + COUNTIFS('S3 Regular Season'!K:K, A38, 'S3 Regular Season'!S:S, "<>") -> 0 | C38: =SUMIF('S3 Regular Season'!A:A, A38, 'S3 Regular Season'!I:I) + SUMIF('S3 Regular Season'!K:K, A38, 'S3 Regular Season'!S:S) -> 0 | D38: =SUMIF(S3_Game_Stats[Name], A38, S3_Game_Stats[Games]) - SUMIF(S3_Game_Stats[Name], A38, S3_Game_Stats[Wins]) -> 0 | E38: =IFERROR(SUMIF(S3_Game_Stats[Name], A38, S3_Game_Stats[Wins]) / SUMIF(S3_Game_Stats[Name], A38, S3_Game_Stats[Games]),"") | F38: =IFERROR(SUMIF(S3_Game_Stats[Name], A38, S3_Game_Stats[Rounds Won]) / SUMIF(S3_Game_Stats[Name], A38, S3_Game_Stats[Rounds Played]),"") | G38: =SUMIF('S3 Regular Season'!A:A, A38, 'S3 Regular Season'!H:H) + SUMIF('S3 Regular Season'!K:K, A38, 'S3 Regular Season'!R:R) -> 0 | H38: =SUMIF(S3_Game_Stats[Name], A38, S3_Game_Stats[Rounds Played]) - SUMIF(S3_Game_Stats[Name], A38, S3_Game_Stats[Rounds Won]) -> 0 | I38: =SUMIF('S3 Regular Season'!A:A, A38, 'S3 Regular Season'!G:G) + SUMIF('S3 Regular Season'!K:K, A38, 'S3 Regular Season'!Q:Q) -> 0 | L38: 5 | M38: Emanuel
A39: Eric | B39: =COUNTIFS('S3 Regular Season'!A:A, A39, 'S3 Regular Season'!I:I, "<>") + COUNTIFS('S3 Regular Season'!K:K, A39, 'S3 Regular Season'!S:S, "<>") -> 0 | C39: =SUMIF('S3 Regular Season'!A:A, A39, 'S3 Regular Season'!I:I) + SUMIF('S3 Regular Season'!K:K, A39, 'S3 Regular Season'!S:S) -> 0 | D39: =SUMIF(S3_Game_Stats[Name], A39, S3_Game_Stats[Games]) - SUMIF(S3_Game_Stats[Name], A39, S3_Game_Stats[Wins]) -> 0 | E39: =IFERROR(SUMIF(S3_Game_Stats[Name], A39, S3_Game_Stats[Wins]) / SUMIF(S3_Game_Stats[Name], A39, S3_Game_Stats[Games]),"") | F39: =IFERROR(SUMIF(S3_Game_Stats[Name], A39, S3_Game_Stats[Rounds Won]) / SUMIF(S3_Game_Stats[Name], A39, S3_Game_Stats[Rounds Played]),"") | G39: =SUMIF('S3 Regular Season'!A:A, A39, 'S3 Regular Season'!H:H) + SUMIF('S3 Regular Season'!K:K, A39, 'S3 Regular Season'!R:R) -> 0 | H39: =SUMIF(S3_Game_Stats[Name], A39, S3_Game_Stats[Rounds Played]) - SUMIF(S3_Game_Stats[Name], A39, S3_Game_Stats[Rounds Won]) -> 0 | I39: =SUMIF('S3 Regular Season'!A:A, A39, 'S3 Regular Season'!G:G) + SUMIF('S3 Regular Season'!K:K, A39, 'S3 Regular Season'!Q:Q) -> 0 | L39: 6 | M39: Eric
A40: Fred | B40: =COUNTIFS('S3 Regular Season'!A:A, A40, 'S3 Regular Season'!I:I, "<>") + COUNTIFS('S3 Regular Season'!K:K, A40, 'S3 Regular Season'!S:S, "<>") -> 0 | C40: =SUMIF('S3 Regular Season'!A:A, A40, 'S3 Regular Season'!I:I) + SUMIF('S3 Regular Season'!K:K, A40, 'S3 Regular Season'!S:S) -> 0 | D40: =SUMIF(S3_Game_Stats[Name], A40, S3_Game_Stats[Games]) - SUMIF(S3_Game_Stats[Name], A40, S3_Game_Stats[Wins]) -> 0 | E40: =IFERROR(SUMIF(S3_Game_Stats[Name], A40, S3_Game_Stats[Wins]) / SUMIF(S3_Game_Stats[Name], A40, S3_Game_Stats[Games]),"") | F40: =IFERROR(SUMIF(S3_Game_Stats[Name], A40, S3_Game_Stats[Rounds Won]) / SUMIF(S3_Game_Stats[Name], A40, S3_Game_Stats[Rounds Played]),"") | G40: =SUMIF('S3 Regular Season'!A:A, A40, 'S3 Regular Season'!H:H) + SUMIF('S3 Regular Season'!K:K, A40, 'S3 Regular Season'!R:R) -> 0 | H40: =SUMIF(S3_Game_Stats[Name], A40, S3_Game_Stats[Rounds Played]) - SUMIF(S3_Game_Stats[Name], A40, S3_Game_Stats[Rounds Won]) -> 0 | I40: =SUMIF('S3 Regular Season'!A:A, A40, 'S3 Regular Season'!G:G) + SUMIF('S3 Regular Season'!K:K, A40, 'S3 Regular Season'!Q:Q) -> 0 | L40: 7 | M40: Fred
A41: Kevin | B41: =COUNTIFS('S3 Regular Season'!A:A, A41, 'S3 Regular Season'!I:I, "<>") + COUNTIFS('S3 Regular Season'!K:K, A41, 'S3 Regular Season'!S:S, "<>") -> 0 | C41: =SUMIF('S3 Regular Season'!A:A, A41, 'S3 Regular Season'!I:I) + SUMIF('S3 Regular Season'!K:K, A41, 'S3 Regular Season'!S:S) -> 0 | D41: =SUMIF(S3_Game_Stats[Name], A41, S3_Game_Stats[Games]) - SUMIF(S3_Game_Stats[Name], A41, S3_Game_Stats[Wins]) -> 0 | E41: =IFERROR(SUMIF(S3_Game_Stats[Name], A41, S3_Game_Stats[Wins]) / SUMIF(S3_Game_Stats[Name], A41, S3_Game_Stats[Games]),"") | F41: =IFERROR(SUMIF(S3_Game_Stats[Name], A41, S3_Game_Stats[Rounds Won]) / SUMIF(S3_Game_Stats[Name], A41, S3_Game_Stats[Rounds Played]),"") | G41: =SUMIF('S3 Regular Season'!A:A, A41, 'S3 Regular Season'!H:H) + SUMIF('S3 Regular Season'!K:K, A41, 'S3 Regular Season'!R:R) -> 0 | H41: =SUMIF(S3_Game_Stats[Name], A41, S3_Game_Stats[Rounds Played]) - SUMIF(S3_Game_Stats[Name], A41, S3_Game_Stats[Rounds Won]) -> 0 | I41: =SUMIF('S3 Regular Season'!A:A, A41, 'S3 Regular Season'!G:G) + SUMIF('S3 Regular Season'!K:K, A41, 'S3 Regular Season'!Q:Q) -> 0 | L41: 8 | M41: Kevin
A42: Michael | B42: =COUNTIFS('S3 Regular Season'!A:A, A42, 'S3 Regular Season'!I:I, "<>") + COUNTIFS('S3 Regular Season'!K:K, A42, 'S3 Regular Season'!S:S, "<>") -> 0 | C42: =SUMIF('S3 Regular Season'!A:A, A42, 'S3 Regular Season'!I:I) + SUMIF('S3 Regular Season'!K:K, A42, 'S3 Regular Season'!S:S) -> 0 | D42: =SUMIF(S3_Game_Stats[Name], A42, S3_Game_Stats[Games]) - SUMIF(S3_Game_Stats[Name], A42, S3_Game_Stats[Wins]) -> 0 | E42: =IFERROR(SUMIF(S3_Game_Stats[Name], A42, S3_Game_Stats[Wins]) / SUMIF(S3_Game_Stats[Name], A42, S3_Game_Stats[Games]),"") | F42: =IFERROR(SUMIF(S3_Game_Stats[Name], A42, S3_Game_Stats[Rounds Won]) / SUMIF(S3_Game_Stats[Name], A42, S3_Game_Stats[Rounds Played]),"") | G42: =SUMIF('S3 Regular Season'!A:A, A42, 'S3 Regular Season'!H:H) + SUMIF('S3 Regular Season'!K:K, A42, 'S3 Regular Season'!R:R) -> 0 | H42: =SUMIF(S3_Game_Stats[Name], A42, S3_Game_Stats[Rounds Played]) - SUMIF(S3_Game_Stats[Name], A42, S3_Game_Stats[Rounds Won]) -> 0 | I42: =SUMIF('S3 Regular Season'!A:A, A42, 'S3 Regular Season'!G:G) + SUMIF('S3 Regular Season'!K:K, A42, 'S3 Regular Season'!Q:Q) -> 0 | L42: 9 | M42: Michael
A43: Sean | B43: =COUNTIFS('S3 Regular Season'!A:A, A43, 'S3 Regular Season'!I:I, "<>") + COUNTIFS('S3 Regular Season'!K:K, A43, 'S3 Regular Season'!S:S, "<>") -> 0 | C43: =SUMIF('S3 Regular Season'!A:A, A43, 'S3 Regular Season'!I:I) + SUMIF('S3 Regular Season'!K:K, A43, 'S3 Regular Season'!S:S) -> 0 | D43: =SUMIF(S3_Game_Stats[Name], A43, S3_Game_Stats[Games]) - SUMIF(S3_Game_Stats[Name], A43, S3_Game_Stats[Wins]) -> 0 | E43: =IFERROR(SUMIF(S3_Game_Stats[Name], A43, S3_Game_Stats[Wins]) / SUMIF(S3_Game_Stats[Name], A43, S3_Game_Stats[Games]),"") | F43: =IFERROR(SUMIF(S3_Game_Stats[Name], A43, S3_Game_Stats[Rounds Won]) / SUMIF(S3_Game_Stats[Name], A43, S3_Game_Stats[Rounds Played]),"") | G43: =SUMIF('S3 Regular Season'!A:A, A43, 'S3 Regular Season'!H:H) + SUMIF('S3 Regular Season'!K:K, A43, 'S3 Regular Season'!R:R) -> 0 | H43: =SUMIF(S3_Game_Stats[Name], A43, S3_Game_Stats[Rounds Played]) - SUMIF(S3_Game_Stats[Name], A43, S3_Game_Stats[Rounds Won]) -> 0 | I43: =SUMIF('S3 Regular Season'!A:A, A43, 'S3 Regular Season'!G:G) + SUMIF('S3 Regular Season'!K:K, A43, 'S3 Regular Season'!Q:Q) -> 0 | K43: Play-in | L43: 10 | M43: Sean
A44: Steve | B44: =COUNTIFS('S3 Regular Season'!A:A, A44, 'S3 Regular Season'!I:I, "<>") + COUNTIFS('S3 Regular Season'!K:K, A44, 'S3 Regular Season'!S:S, "<>") -> 0 | C44: =SUMIF('S3 Regular Season'!A:A, A44, 'S3 Regular Season'!I:I) + SUMIF('S3 Regular Season'!K:K, A44, 'S3 Regular Season'!S:S) -> 0 | D44: =SUMIF(S3_Game_Stats[Name], A44, S3_Game_Stats[Games]) - SUMIF(S3_Game_Stats[Name], A44, S3_Game_Stats[Wins]) -> 0 | E44: =IFERROR(SUMIF(S3_Game_Stats[Name], A44, S3_Game_Stats[Wins]) / SUMIF(S3_Game_Stats[Name], A44, S3_Game_Stats[Games]),"") | F44: =IFERROR(SUMIF(S3_Game_Stats[Name], A44, S3_Game_Stats[Rounds Won]) / SUMIF(S3_Game_Stats[Name], A44, S3_Game_Stats[Rounds Played]),"") | G44: =SUMIF('S3 Regular Season'!A:A, A44, 'S3 Regular Season'!H:H) + SUMIF('S3 Regular Season'!K:K, A44, 'S3 Regular Season'!R:R) -> 0 | H44: =SUMIF(S3_Game_Stats[Name], A44, S3_Game_Stats[Rounds Played]) - SUMIF(S3_Game_Stats[Name], A44, S3_Game_Stats[Rounds Won]) -> 0 | I44: =SUMIF('S3 Regular Season'!A:A, A44, 'S3 Regular Season'!G:G) + SUMIF('S3 Regular Season'!K:K, A44, 'S3 Regular Season'!Q:Q) -> 0 | L44: 11 | M44: Steve
...

Sheet S3 Regular Season
J1: Week 1 | M1: BYE | O1: Kevin | T1: Week 1
A2: 4 | D2: GAME OF THE WEEK | J2: Final Score
V3: REMEMBER TO SCREENSHOT THE FINAL SCOREBOARD
A4: Shirts | B4: K | C4: A | D4: D | E4: ADR | F4: DMG | G4: Rounds | H4: Rounds Won | I4: Win | K4: Skins | L4: K | M4: A | N4: D | O4: ADR | P4: DMG | Q4: Rounds | R4: Rounds Won | S4: Win | U4: Shirts Ban | V4: Skins Ban 1 | W4: Skins Ban 2 | X4: Shirts Pick | Y4: Skins Side
A5: Sean | G5: =IFERROR(__xludf.DUMMYFUNCTION("IFERROR(SUM(SPLIT(J3, ""-"")))"),"") | H5: =IFERROR(__xludf.DUMMYFUNCTION("IFERROR(INDEX(SPLIT($J3, ""-""), 0, 1))"),"") | K5: Tim | Q5: =IFERROR(__xludf.DUMMYFUNCTION("IFERROR(SUM(SPLIT(J3, ""-"")))"),"") | R5: =IFERROR(__xludf.DUMMYFUNCTION("IFERROR(INDEX(SPLIT($J3, ""-""), 0, 2))"),"")
A6: Fred | G6: =IFERROR(__xludf.DUMMYFUNCTION("IFERROR(SUM(SPLIT(J3, ""-"")))"),"") | H6: =IFERROR(__xludf.DUMMYFUNCTION("IFERROR(INDEX(SPLIT($J3, ""-""), 0, 1))"),"") | K6: Adam | Q6: =IFERROR(__xludf.DUMMYFUNCTION("IFERROR(SUM(SPLIT(J3, ""-"")))"),"") | R6: =IFERROR(__xludf.DUMMYFUNCTION("IFERROR(INDEX(SPLIT($J3, ""-""), 0, 2))"),"")
A8: 5 | J8: Final Score
V10: REMEMBER TO SCREENSHOT THE FINAL SCOREBOARD
A11: Shirts | B11: K | C11: A | D11: D | E11: ADR | F11: DMG | G11: Rounds | H11: Rounds Won | I11: Column 9 | K11: Skins | L11: K | M11: A | N11: D | O11: ADR | P11: DMG | Q11: Rounds | R11: Rounds Won | S11: Column 9 | U11: Shirts Ban | V11: Skins Ban 1 | W11: Skins Ban 2 | X11: Shirts Pick | Y11: Skins Side
A12: Brian | G12: =IFERROR(__xludf.DUMMYFUNCTION("IFERROR(SUM(SPLIT(J9, ""-"")))"),"") | H12: =IFERROR(__xludf.DUMMYFUNCTION("IFERROR(INDEX(SPLIT($J9, ""-""), 0, 1))"),"") | K12: Dan | Q12: =IFERROR(__xludf.DUMMYFUNCTION("IFERROR(SUM(SPLIT(J9, ""-"")))"),"") | R12: =IFERROR(__xludf.DUMMYFUNCTION("IFERROR(INDEX(SPLIT($J9, ""-""), 0, 2))"),"")
A13: Eric | G13: =IFERROR(__xludf.DUMMYFUNCTION("IFERROR(SUM(SPLIT(J9, ""-"")))"),"") | H13: =IFERROR(__xludf.DUMMYFUNCTION("IFERROR(INDEX(SPLIT($J9, ""-""), 0, 1))"),"") | K13: Michael | Q13: =IFERROR(__xludf.DUMMYFUNCTION("IFERROR(SUM(SPLIT(J9, ""-"")))"),"") | R13: =IFERROR(__xludf.DUMMYFUNCTION("IFERROR(INDEX(SPLIT($J9, ""-""), 0, 2))"),"")
A16: 6 | J16: Final Score
V18: REMEMBER TO SCREENSHOT THE FINAL SCOREBOARD
A19: Shirts | B19: K | C19: A | D19: D | E19: ADR | F19: DMG | G19: Rounds | H19: Rounds Won | I19: Column 9 | K19: Skins | L19: K | M19: A | N19: D | O19: ADR | P19: DMG | Q19: Rounds | R19: Rounds Won | S19: Column 9 | U19: Shirts Ban | V19: Skins Ban 1 | W19: Skins Ban 2 | X19: Shirts Pick | Y19: Skins Side
A20: Zach | G20: =IFERROR(__xludf.DUMMYFUNCTION("IFERROR(SUM(SPLIT(J17, ""-"")))"),"") | H20: =IFERROR(__xludf.DUMMYFUNCTION("IFERROR(INDEX(SPLIT($J17, ""-""), 0, 1))"),"") | K20: Andrew | Q20: =IFERROR(__xludf.DUMMYFUNCTION("IFERROR(SUM(SPLIT(J17, ""-"")))"),"") | R20: =IFERROR(__xludf.DUMMYFUNCTION("IFERROR(INDEX(SPLIT($J17, ""-""), 0, 2))"),"")
A21: Steve | G21: =IFERROR(__xludf.DUMMYFUNCTION("IFERROR(SUM(SPLIT(J17, ""-"")))"),"") | H21: =IFERROR(__xludf.DUMMYFUNCTION("IFERROR(INDEX(SPLIT($J17, ""-""), 0, 1))"),"") | K21: Emanuel | Q21: =IFERROR(__xludf.DUMMYFUNCTION("IFERROR(SUM(SPLIT(J17, ""-"")))"),"") | R21: =IFERROR(__xludf.DUMMYFUNCTION("IFERROR(INDEX(SPLIT($J17, ""-""), 0, 2))"),"")
J23: Week 2 | M23: BYE | O23: Adam | T23: Week 2
A24: 10 | E24: GAME OF THE WEEK | J24: Final Score
V25: REMEMBER TO SCREENSHOT THE FINAL SCOREBOARD
A26: Shirts | B26: K | C26: A | D26: D | E26: ADR | F26: DMG | G26: Rounds | H26: Rounds Won | I26: Win | K26: Skins | L26: K | M26: A | N26: D | O26: ADR | P26: DMG | Q26: Rounds | R26: Rounds Won | S26: Win | U26: Shirts Ban | V26: Skins Ban 1 | W26: Skins Ban 2 | X26: Shirts Pick | Y26: Skins Side
A27: Eric | G27: =IFERROR(__xludf.DUMMYFUNCTION("IFERROR(SUM(SPLIT(J25, ""-"")))"),"") | H27: =IFERROR(__xludf.DUMMYFUNCTION("IFERROR(INDEX(SPLIT($J25, ""-""), 0, 1))"),"") | K27: Zach | Q27: =IFERROR(__xludf.DUMMYFUNCTION("IFERROR(SUM(SPLIT(J25, ""-"")))"),"") | R27: =IFERROR(__xludf.DUMMYFUNCTION("IFERROR(INDEX(SPLIT($J25, ""-""), 0, 2))"),"")
A28: Kevin | G28: =IFERROR(__xludf.DUMMYFUNCTION("IFERROR(SUM(SPLIT(J25, ""-"")))"),"") | H28: =IFERROR(__xludf.DUMMYFUNCTION("IFERROR(INDEX(SPLIT($J25, ""-""), 0, 1))"),"") | K28: Emanuel | Q28: =IFERROR(__xludf.DUMMYFUNCTION("IFERROR(SUM(SPLIT(J25, ""-"")))"),"") | R28: =IFERROR(__xludf.DUMMYFUNCTION("IFERROR(INDEX(SPLIT($J25, ""-""), 0, 2))"),"")
A30: 11 | J30: Final Score
V32: REMEMBER TO SCREENSHOT THE FINAL SCOREBOARD
A33: Shirts | B33: K | C33: A | D33: D | E33: ADR | F33: DMG | G33: Rounds | H33: Rounds Won | I33: Column 9 | K33: Skins | L33: K | M33: A | N33: D | O33: ADR | P33: DMG | Q33: Rounds | R33: Rounds Won | S33: Column 9 | U33: Shirts Ban | V33: Skins Ban 1 | W33: Skins Ban 2 | X33: Shirts Pick | Y33: Skins Side
A34: Sean | G34: =IFERROR(__xludf.DUMMYFUNCTION("IFERROR(SUM(SPLIT(J31, ""-"")))"),"") | H34: =IFERROR(__xludf.DUMMYFUNCTION("IFERROR(INDEX(SPLIT($J31, ""-""), 0, 1))"),"") | K34: Brian | Q34: =IFERROR(__xludf.DUMMYFUNCTION("IFERROR(SUM(SPLIT(J31, ""-"")))"),"") | R34: =IFERROR(__xludf.DUMMYFUNCTION("IFERROR(INDEX(SPLIT($J31, ""-""), 0, 2))"),"")
A35: Steve | G35: =IFERROR(__xludf.DUMMYFUNCTION("IFERROR(SUM(SPLIT(J31, ""-"")))"),"") | H35: =IFERROR(__xludf.DUMMYFUNCTION("IFERROR(INDEX(SPLIT($J31, ""-""), 0, 1))"),"") | K35: Andrew | Q35: =IFERROR(__xludf.DUMMYFUNCTION("IFERROR(SUM(SPLIT(J31, ""-"")))"),"") | R35: =IFERROR(__xludf.DUMMYFUNCTION("IFERROR(INDEX(SPLIT($J31, ""-""), 0, 2))"),"")
A38: 12 | J38: Final Score
V40: REMEMBER TO SCREENSHOT THE FINAL SCOREBOARD
A41: Shirts | B41: K | C41: A | D41: D | E41: ADR | F41: DMG | G41: Rounds | H41: Rounds Won | I41: Column 9 | K41: Skins | L41: K | M41: A | N41: D | O41: ADR | P41: DMG | Q41: Rounds | R41: Rounds Won | S41: Column 9 | U41: Shirts Ban | V41: Skins Ban 1 | W41: Skins Ban 2 | X41: Shirts Pick | Y41: Skins Side
A42: Dan | G42: =IFERROR(__xludf.DUMMYFUNCTION("IFERROR(SUM(SPLIT(J39, ""-"")))"),"") | H42: =IFERROR(__xludf.DUMMYFUNCTION("IFERROR(INDEX(SPLIT($J39, ""-""), 0, 1))"),"") | K42: Michael | Q42: =IFERROR(__xludf.DUMMYFUNCTION("IFERROR(SUM(SPLIT(J39, ""-"")))"),"") | R42: =IFERROR(__xludf.DUMMYFUNCTION("IFERROR(INDEX(SPLIT($J39, ""-""), 0, 2))"),"")
A43: Tim | G43: =IFERROR(__xludf.DUMMYFUNCTION("IFERROR(SUM(SPLIT(J39, ""-"")))"),"") | H43: =IFERROR(__xludf.DUMMYFUNCTION("IFERROR(INDEX(SPLIT($J39, ""-""), 0, 1))"),"") | K43: Fred | Q43: =IFERROR(__xludf.DUMMYFUNCTION("IFERROR(SUM(SPLIT(J39, ""-"")))"),"") | R43: =IFERROR(__xludf.DUMMYFUNCTION("IFERROR(INDEX(SPLIT($J39, ""-""), 0, 2))"),"")
J45: Week 3 | M45: BYE | O45: Sean | T45: Week 3
A46: 1 | E46: GAME OF THE WEEK | J46: Final Score
V47: REMEMBER TO SCREENSHOT THE FINAL SCOREBOARD
A48: Shirts | B48: K | C48: A | D48: D | E48: ADR | F48: DMG | G48: Rounds | H48: Rounds Won | I48: Win | K48: Skins | L48: K | M48: A | N48: D | O48: ADR | P48: DMG | Q48: Rounds | R48: Rounds Won | S48: Win | U48: Shirts Ban | V48: Skins Ban 1 | W48: Skins Ban 2 | X48: Shirts Pick | Y48: Skins Side
A49: Zach | G49: =IFERROR(__xludf.DUMMYFUNCTION("IFERROR(SUM(SPLIT(J47, ""-"")))"),"") | H49: =IFERROR(__xludf.DUMMYFUNCTION("IFERROR(INDEX(SPLIT($J47, ""-""), 0, 1))"),"") | K49: Brian | Q49: =IFERROR(__xludf.DUMMYFUNCTION("IFERROR(SUM(SPLIT(J47, ""-"")))"),"") | R49: =IFERROR(__xludf.DUMMYFUNCTION("IFERROR(INDEX(SPLIT($J47, ""-""), 0, 2))"),"")
A50: Fred | G50: =IFERROR(__xludf.DUMMYFUNCTION("IFERROR(SUM(SPLIT(J47, ""-"")))"),"") | H50: =IFERROR(__xludf.DUMMYFUNCTION("IFERROR(INDEX(SPLIT($J47, ""-""), 0, 1))"),"") | K50: Kevin | Q50: =IFERROR(__xludf.DUMMYFUNCTION("IFERROR(SUM(SPLIT(J47, ""-"")))"),"") | R50: =IFERROR(__xludf.DUMMYFUNCTION("IFERROR(INDEX(SPLIT($J47, ""-""), 0, 2))"),"")
A52: 2 | J52: Final Score
V54: REMEMBER TO SCREENSHOT THE FINAL SCOREBOARD
...

Sheet Schedule Difficulty Calculator
A1: Wins leaders | B1: Rating Value | C1: prem | D1: last szn placement + random # for new | H1: Estimated Schedule Difficulty | K1: max for normalization
A2: Zach | B2: 12264 | C2: 12264 | D2: 8 | G2: Name | H2: RAW | I2: Relative Difficulty | K2: =MAX(H3:H14) -> 138695
A3: Dan | B3: 20844 | C3: 20844 | D3: 8 | G3: Adam | H3: =SUMIF($C$17:$C$55,G3,$A$17:$A$55)+SUMIF($D$17:$D$55,G3,$B$17:$B$55)+SUMIF($G$17:$G$55,G3,$I$17:$I$55)+SUMIF($H$17:$H$55,G3,$J$17:$J$55) -> 129594 | I3: =H3/$K$2 -> 0.9343812
A4: Brian | B4: 12316 | C4: 12316 | D4: 6 | G4: Andrew | H4: =SUMIF($C$17:$C$55,G4,$A$17:$A$55)+SUMIF($D$17:$D$55,G4,$B$17:$B$55)+SUMIF($G$17:$G$55,G4,$I$17:$I$55)+SUMIF($H$17:$H$55,G4,$J$17:$J$55) -> 95168 | I4: =H4/$K$2 -> 0.68616749 | K4: Relative Difficulty: The closer to 100%, the more difficult the schedule
A5: Adam | B5: 15691 | C5: 15691 | D5: 5 | G5: Brian | H5: =SUMIF($C$17:$C$55,G5,$A$17:$A$55)+SUMIF($D$17:$D$55,G5,$B$17:$B$55)+SUMIF($G$17:$G$55,G5,$I$17:$I$55)+SUMIF($H$17:$H$55,G5,$J$17:$J$55) -> 116168 | I5: =H5/$K$2 -> 0.83757886
A6: Sean | B6: 17486 | C6: 17486 | D6: 9 | G6: Dan | H6: =SUMIF($C$17:$C$55,G6,$A$17:$A$55)+SUMIF($D$17:$D$55,G6,$B$17:$B$55)+SUMIF($G$17:$G$55,G6,$I$17:$I$55)+SUMIF($H$17:$H$55,G6,$J$17:$J$55) -> 122125 | I6: =H6/$K$2 -> 0.88052922
A7: Eric | B7: 8500 | C7: 8500 | D7: 5 | G7: Emanuel | H7: =SUMIF($C$17:$C$55,G7,$A$17:$A$55)+SUMIF($D$17:$D$55,G7,$B$17:$B$55)+SUMIF($G$17:$G$55,G7,$I$17:$I$55)+SUMIF($H$17:$H$55,G7,$J$17:$J$55) -> 112445 | I7: =H7/$K$2 -> 0.81073579
A8: Tim | B8: 2500 | C8: 2500 | D8: 3 | G8: eric | H8: =SUMIF($C$17:$C$55,G8,$A$17:$A$55)+SUMIF($D$17:$D$55,G8,$B$17:$B$55)+SUMIF($G$17:$G$55,G8,$I$17:$I$55)+SUMIF($H$17:$H$55,G8,$J$17:$J$55) -> 138695 | I8: =H8/$K$2 -> 1
A9: Emanuel | B9: 3105 | C9: 2500 | D9: 5 | G9: Sean | H9: =SUMIF($C$17:$C$55,G9,$A$17:$A$55)+SUMIF($D$17:$D$55,G9,$B$17:$B$55)+SUMIF($G$17:$G$55,G9,$I$17:$I$55)+SUMIF($H$17:$H$55,G9,$J$17:$J$55) -> 116827 | I9: =H9/$K$2 -> 0.84233029
A10: Andrew | B10: 1153 | C10: 2500 | D10: 1 | G10: Tim | H10: =SUMIF($C$17:$C$55,G10,$A$17:$A$55)+SUMIF($D$17:$D$55,G10,$B$17:$B$55)+SUMIF($G$17:$G$55,G10,$I$17:$I$55)+SUMIF($H$17:$H$55,G10,$J$17:$J$55) -> 118852 | I10: =H10/$K$2 -> 0.85693068
A11: Kevin | B11: 3500 | C11: 3500 | D11: 3 | G11: Zach | H11: =SUMIF($C$17:$C$55,G11,$A$17:$A$55)+SUMIF($D$17:$D$55,G11,$B$17:$B$55)+SUMIF($G$17:$G$55,G11,$I$17:$I$55)+SUMIF($H$17:$H$55,G11,$J$17:$J$55) -> 98906 | I11: =H11/$K$2 -> 0.71311871
A12: Steve | B12: 7000 | C12: 7000 | D12: 3 | G12: steve | H12: =SUMIF($C$17:$C$55,G12,$A$17:$A$55)+SUMIF($D$17:$D$55,G12,$B$17:$B$55)+SUMIF($G$17:$G$55,G12,$I$17:$I$55)+SUMIF($H$17:$H$55,G12,$J$17:$J$55) -> 132081 | I12: =H12/$K$2 -> 0.95231263
A13: michael | B13: 3500 | C13: 3500 | D13: 3 | G13: michael | H13: =SUMIF($C$17:$C$55,G13,$A$17:$A$55)+SUMIF($D$17:$D$55,G13,$B$17:$B$55)+SUMIF($G$17:$G$55,G13,$I$17:$I$55)+SUMIF($H$17:$H$55,G13,$J$17:$J$55) -> 131785 | I13: =H13/$K$2 -> 0.95017845
A14: Fred | B14: 1000 | C14: 1000 | D14: 1 | G14: fred | H14: =SUMIF($C$17:$C$55,G14,$A$17:$A$55)+SUMIF($D$17:$D$55,G14,$B$17:$B$55)+SUMIF($G$17:$G$55,G14,$I$17:$I$55)+SUMIF($H$17:$H$55,G14,$J$17:$J$55) -> 112213 | I14: =H14/$K$2 -> 0.80906305
A15: T 1 | G15: T 2
A16: P1 DIF VAL | B16: P2 DIF VAL | C16: names | E16: Raw Closeness | F16: Normalized 0-100 | G16: names | I16: P1 DIF VAL | J16: P2 DIF VAL | L16: GAME NUM
A17: =MAX(XLOOKUP(G17,$A$2:$A$14,$B$2:$B$14)+XLOOKUP(H17,$A$2:$A$14,$B$2:$B$14)-XLOOKUP(D17,$A$2:$A$14,$B$2:$B$14),0) -> 14816 | B17: =MAX(XLOOKUP(G17,$A$2:$A$14,$B$2:$B$14)+XLOOKUP(H17,$A$2:$A$14,$B$2:$B$14)-XLOOKUP(C17,$A$2:$A$14,$B$2:$B$14),0) -> 3552 | C17: Zach | D17: Fred | E17: =(A17 + B17 - I17 - J17)/1000 -> 7.656 | F17: =E17/$E$57*100 -> 10.990525 | G17: Brian | H17: Kevin | I17: =MAX(XLOOKUP(C17,$A$2:$A$14,$B$2:$B$14)+XLOOKUP(D17,$A$2:$A$14,$B$2:$B$14)-XLOOKUP(H17,$A$2:$A$14,$B$2:$B$14),0) -> 9764 | J17: =MAX(XLOOKUP(C17,$A$2:$A$14,$B$2:$B$14)+XLOOKUP(D17,$A$2:$A$14,$B$2:$B$14)-XLOOKUP(G17,$A$2:$A$14,$B$2:$B$14),0) -> 948 | L17: 1
A18: =MAX(XLOOKUP(G18,$A$2:$A$14,$B$2:$B$14)+XLOOKUP(H18,$A$2:$A$14,$B$2:$B$14)-XLOOKUP(D18,$A$2:$A$14,$B$2:$B$14),0) -> 4000 | B18: =MAX(XLOOKUP(G18,$A$2:$A$14,$B$2:$B$14)+XLOOKUP(H18,$A$2:$A$14,$B$2:$B$14)-XLOOKUP(C18,$A$2:$A$14,$B$2:$B$14),0) -> 0 | C18: Dan | D18: Steve | E18: =(A18 + B18 - I18 - J18)/1000 -> -40.688 | F18: =E18/$E$57*100 -> -58.409417 | G18: Tim | H18: Eric | I18: =MAX(XLOOKUP(C18,$A$2:$A$14,$B$2:$B$14)+XLOOKUP(D18,$A$2:$A$14,$B$2:$B$14)-XLOOKUP(H18,$A$2:$A$14,$B$2:$B$14),0) -> 19344 | J18: =MAX(XLOOKUP(C18,$A$2:$A$14,$B$2:$B$14)+XLOOKUP(D18,$A$2:$A$14,$B$2:$B$14)-XLOOKUP(G18,$A$2:$A$14,$B$2:$B$14),0) -> 25344 | L18: 2
A19: =MAX(XLOOKUP(G19,$A$2:$A$14,$B$2:$B$14)+XLOOKUP(H19,$A$2:$A$14,$B$2:$B$14)-XLOOKUP(D19,$A$2:$A$14,$B$2:$B$14),0) -> 15296 | B19: =MAX(XLOOKUP(G19,$A$2:$A$14,$B$2:$B$14)+XLOOKUP(H19,$A$2:$A$14,$B$2:$B$14)-XLOOKUP(C19,$A$2:$A$14,$B$2:$B$14),0) -> 17643 | C19: Andrew | D19: Michael | E19: =(A19 + B19 - I19 - J19)/1000 -> 31.391 | F19: =E19/$E$57*100 -> 45.063164 | G19: Emanuel | H19: Adam | I19: =MAX(XLOOKUP(C19,$A$2:$A$14,$B$2:$B$14)+XLOOKUP(D19,$A$2:$A$14,$B$2:$B$14)-XLOOKUP(H19,$A$2:$A$14,$B$2:$B$14),0) -> 0 | J19: =MAX(XLOOKUP(C19,$A$2:$A$14,$B$2:$B$14)+XLOOKUP(D19,$A$2:$A$14,$B$2:$B$14)-XLOOKUP(G19,$A$2:$A$14,$B$2:$B$14),0) -> 1548 | L19: 3
